Workbook

Sheet 2026
A2: Escalón | B2: Sueldo Fijo Retirable | C2: Facturación Promedio (3 meses) | D2: Colchón Mínimo en FM | E2: Regla de Bajada
A3: Escalón 1 | B3: ₲600.000 | C3: Base de partida | D3: Acumular hasta ₲2.000.000 | E3: Piso base (no baja más)
A4: Escalón 2 | B4: ₲1.000.000 | C4: ₲1.700.000 / mes | D4: ₲2.000.000 | E4: Si Colchón < ₲1.000.000 tras 3 meses bajos → Vuelve a ₲600.000
A5: Escalón 3 | B5: ₲1.500.000 | C5: ₲2.500.000 / mes | D5: ₲4.500.000 | E5: Si Colchón <₲2.250.000 tras 3 meses bajos → Vuelve a ₲1.000.000
A6: Escalón 4 | B6: ₲2.000.000 | C6: ₲3.350.000 / mes | D6: ₲6.000.000 | E6: Si Colchón $<$ ₲3.000.000 tras 3 meses bajos → Vuelve a ₲1.500.000
A8: Categoría | B8: Ingreso | C8: IVA | D8: Gastos Operativos | E8: Reserva Operativa | F8: Reinversión | G8: Utilidad | H8: Sueldo
A9: Porcentaje | C9: 0.1 | D9: 0.15 | E9: 0.05 | F9: 0.1 | G9: 0.6
A10: Propósito | C10: Monto intocable para la liquidación mensual/trimestral. | D10: Hosting, herramientas, suscripciones básicas. | E10: Pequeño colchón propio de la empresa (para meses de bajos ingresos). | F10: Capacitación, Google IA, mejoras de hardware. | G10: Colchol de salarios | H10: Basado en los 3 ultimos meses
A11: Enero | B11: 1100000 | C11: =B11/11 -> 100000 | D11: =B11*0.15 -> 165000 | E11: =B11*0.05 -> 55000 | F11: =B11*0.1 -> 110000 | G11: =B11-sum(C11:F11) -> 670000 | H11: 0
A12: Febrero | B12: 4730000 | C12: =B12/11 -> 430000 | D12: =B12*0.15 -> 709500 | E12: =B12*0.05 -> 236500 | F12: =B12*0.1 -> 473000 | G12: =B12-sum(C12:F12) -> 2881000 | H12: 0
A13: Marzo | B13: 500000 | C13: =B13/11 -> 45454.545 | D13: =B13*0.15 -> 75000 | E13: =B13*0.05 -> 25000 | F13: =B13*0.1 -> 50000 | G13: =B13-sum(C13:F13) -> 304545.45 | H13: 0
A14: Abril | B14: 1730000 | C14: =B14/11 -> 157272.73 | D14: =B14*0.15 -> 259500 | E14: =B14*0.05 -> 86500 | F14: =B14*0.1 -> 173000 | G14: =B14-sum(C14:F14) -> 1053727.3 | H14: 0
A15: Mayo | B15: 1420000 | C15: =B15/11 -> 129090.91 | D15: =B15*0.15 -> 213000 | E15: =B15*0.05 -> 71000 | F15: =B15*0.1 -> 142000 | G15: =B15-sum(C15:F15) -> 864909.09 | H15: 0
A16: Junio | B16: 1122000 | C16: =B16/11 -> 102000 | D16: =B16*0.15 -> 168300 | E16: =B16*0.05 -> 56100 | F16: =B16*0.1 -> 112200 | G16: =B16-sum(C16:F16) -> 683400 | H16: 0
A17: Julio | B17: 2238000 | C17: =B17/11 -> 203454.55 | D17: =B17*0.15 -> 335700 | E17: =B17*0.05 -> 111900 | F17: =B17*0.1 -> 223800 | G17: =B17-sum(C17:F17) -> 1363145.5 | H17: 0
A18: Agosto | B18: 2600000 | C18: =B18/11 -> 236363.64 | D18: =B18*0.15 -> 390000 | E18: =B18*0.05 -> 130000 | F18: =B18*0.1 -> 260000 | G18: =B18-sum(C18:F18) -> 1583636.4 | H18: 600000
A19: Septiembre | C19: =B19/11 -> 0 | D19: =B19*0.15 -> 0 | E19: =B19*0.05 -> 0 | F19: =B19*0.1 -> 0 | G19: =B19-sum(C19:F19) -> 0
A20: Octubre | C20: =B20/11 -> 0 | D20: =B20*0.15 -> 0 | E20: =B20*0.05 -> 0 | F20: =B20*0.1 -> 0 | G20: =B20-sum(C20:F20) -> 0
A21: Noviembre | C21: =B21/11 -> 0 | D21: =B21*0.15 -> 0 | E21: =B21*0.05 -> 0 | F21: =B21*0.1 -> 0 | G21: =B21-sum(C21:F21) -> 0
A22: Diciembre | C22: =B22/11 -> 0 | D22: =B22*0.15 -> 0 | E22: =B22*0.05 -> 0 | F22: =B22*0.1 -> 0 | G22: =B22-sum(C22:F22) -> 0
A23: Total Ingreso Anual | B23: =sum(B11:B22) -> 15440000 | G23: =sum(G11:G22) -> 9404363.6 | H23: =sum(H11:H22) -> 600000
A24: Colchon | G24: =sum(G18:G22) -> 1583636.4
A26: Registro de egresos mensual | C26: IVA | D26: Gastos Operativos | E26: Reserva Operativa | F26: Reinversión
A27: Enero | C27: 0 | D27: =220000+160000+62292 -> 442292
A28: Febrero | C28: 50000 | D28: =1049241+25000 -> 1074241
A29: Marzo | C29: =C13 -> 45454.545 | D29: 25017 | E29: 100000
A30: Abril | C30: =C14 -> 157272.73
A31: Mayo | C31: =C15 -> 129090.91 | D31: 25000 | F31: 350000
A32: Junio | C32: =C16 -> 102000 | D32: 25045
A33: Julio | C33: =C17 -> 203454.55 | D33: 25045
A34: Agosto | C34: =C18 -> 236363.64 | D34: 223873
A35: Septiembre | C35: =C19 -> 0
A36: Octubre | C36: =C20 -> 0
A37: Noviembre | C37: =C21 -> 0
A38: Diciembre | C38: =C22 -> 0
A39: Total Egresos Anual | C39: =sum(C27:C38) -> 923636.36 | D39: =sum(D27:D38) -> 1840513 | E39: =sum(E27:E38) -> 100000 | F39: =sum(F27:F38) -> 350000 | G39: =sum(C39:F39) -> 3214149.4
A41: Balance mensual | C41: IVA | D41: Gastos Operativos | E41: Reserva Operativa | F41: Reinversión
A42: Enero | C42: =C11-C27 -> 100000 | D42: =D11-D27 -> -277292 | E42: =E11-E27 -> 55000 | F42: =F11-F27 -> 110000
A43: Febrero | C43: =C12-C28 -> 380000 | D43: =D12-D28 -> -364741 | E43: =E12-E28 -> 236500 | F43: =F12-F28 -> 473000
A44: Marzo | C44: =C13-C29 -> 0 | D44: =D13-D29 -> 49983 | E44: =E13-E29 -> -75000 | F44: =F13-F29 -> 50000
...

Sheet 2025
A2: Resumen
A3: Monthly net income | B3: Total | C3: Carry Over | D3: January | E3: February | F3: March | G3: April | H3: May | I3: June | J3: July | K3: Ago | L3: Sep | M3: Oct | N3: Nov | O3: Dec
A4: Ingresos: 100% | B4: =SUM('2025'!$C4:$O4) -> 8000000 | D4: =D25 -> 1480000 | E4: =E25 -> 1230000 | F4: =F25 -> 0 | G4: =G25 -> 0 | H4: =H25 -> 400000 | I4: =I25 -> 150000 | J4: =J25 -> 1520000 | K4: =K25 -> 0 | ... O4: =O25 -> 0
A5: Gastos Operativos: 50% | B5: =SUM('2025'!$C5:$O5) -> 8362953 | D5: =D42 -> 1296810 | E5: =E42 -> 841199 | F5: =F42 -> 25119 | G5: =G42 -> 25005 | H5: =H42 -> 1122393 | I5: =I42 -> 605000 | J5: =J42 -> 25026 | K5: =K42 -> 109035 | ... O5: =O42 -> 0
A6: Reinversión en el Negocio: 25% | B6: =SUM('2025'!$C6:$O6) -> 7935 | D6: =D60 -> 0 | E6: =E60 -> 0 | F6: =F60 -> 0 | G6: =G60 -> 0 | H6: =H60 -> 600 | I6: =I60 -> 225 | J6: =J60 -> 2280 | K6: =K60 -> 0 | ... O6: =O60 -> 0
A7: Salario del Propietario: 15% | B7: =SUM('2025'!$C7:$O7) -> 1064500 | D7: {='2025'!$D$67} -> 148000 | E7: {='2025'!$E$67} -> 123000 | F7: {='2025'!F$67} -> 0 | G7: {='2025'!G$67} -> 0 | H7: {='2025'!H$67} -> 60000 | I7: {='2025'!I$67} -> 22500 | J7: {='2025'!J$67} -> 228000 | K7: {='2025'!K$67} -> 0 | L7: {='2025'!L$67} -> 0 | M7: {='2025'!M$67} -> 445500 | ... O7: {='2025'!O$67} -> 0
A8: Utilidad Neta / Reserva: 10% | B8: =SUM('2025'!$C8:$O8) -> 800000 | D8: =D78 -> 148000 | E8: =E78 -> 123000 | F8: =F78 -> 0 | G8: =G78 -> 0 | H8: =H78 -> 40000 | I8: =I78 -> 15000 | J8: =J78 -> 152000 | K8: =K78 -> 0 | ... O8: =O78 -> 0
A9: Total | B9: =SUM('2025'!$C9:$O9) -> -2235388 | D9: =D4-SUM(D5:D8) -> -112810 | E9: =E4-SUM(E5:E8) -> 142801 | F9: =F4-SUM(F5:F8) -> -25119 | G9: =G4-SUM(G5:G8) -> -25005 | H9: =H4-SUM(H5:H8) -> -822993 | I9: =I4-SUM(I5:I8) -> -492725 | J9: =J4-SUM(J5:J8) -> 1112694 | K9: =K4-SUM(K5:K8) -> -109035 | ... O9: =O4-SUM(O5:O8) -> 0
A13: Ingresos: 100%
A14: Description | B14: Total | C14: Carry Over | D14: January | E14: February | F14: March | G14: April | H14: May | I14: June | J14: July | K14: Ago | L14: Sep | M14: Oct | N14: Nov | O14: Dec
A15: Web | D15: 0 | E15: 0 | F15: 0 | G15: 0 | H15: 0 | I15: 150000 | J15: =1100000+420000 -> 1520000 | K15: 0 | L15: 0 | M15: =1100000+920000+700000 -> 2720000 | N15: 250000
A16: Consulting | D16: 0 | E16: 0 | F16: 0 | G16: 0 | H16: 400000 | I16: 0 | J16: 0 | K16: 0 | L16: 0 | M16: 0
A17: Development | D17: 0 | E17: 0 | F17: 0 | G17: 0 | H17: 0 | I17: 0 | J17: 0 | K17: 0 | L17: 0 | M17: 0
D18: 0 | E18: 0 | F18: 0
D19: 0 | E19: 0 | F19: 0
D20: 0 | E20: 0 | F20: 0
D21: 0 | E21: 0 | F21: 0
D22: 0 | E22: 0 | F22: 0
D23: 0 | E23: 0 | F23: 0
A24: Others | D24: 1480000 | E24: 1230000 | F24: 0 | G24: 0 | H24: 0 | I24: 0 | J24: 0 | K24: 0 | L24: 0 | M24: 250000
A25: Total | B25: =SUM(C25:O25) -> 8000000 | D25: =SUM(D15:D24) -> 1480000 | E25: =SUM(E15:E24) -> 1230000 | F25: =SUM(F15:F24) -> 0 | G25: =SUM(G15:G24) -> 0 | H25: =SUM(H15:H24) -> 400000 | I25: =SUM(I15:I24) -> 150000 | J25: =SUM(J15:J24) -> 1520000 | K25: =SUM(K15:K24) -> 0 | ... O25: =SUM(O15:O24) -> 0
A27: Gastos Operativos: 50%
A28: Description | B28: Total | C28: Carry Over | D28: January | E28: February | F28: March | G28: April | H28: May | I28: June | J28: July | K28: Ago | L28: Sep | M28: Oct | N28: Nov | O28: Dec
A29: Variable - Gross tax (10 %) | B29: =SUM(D29:O29) -> 727272.73 | D29: =D25/11 -> 134545.45 | E29: =E25/11 -> 111818.18 | F29: =F25/11 -> 0 | G29: =G25/11 -> 0 | H29: =H25/11 -> 36363.636 | I29: =I25/11 -> 13636.364 | J29: =J25/11 -> 138181.82 | K29: =K25/11 -> 0 | ... O29: =O25/11 -> 0
A30: Variable - Round up tax | B30: =SUM(D30:O30) -> 720000 | D30: =ROUND(D29,-4) -> 130000 | E30: =ROUND(E29,-4) -> 110000 | F30: =ROUND(F29,-4) -> 0 | G30: =ROUND(G29,-4) -> 0 | H30: =ROUND(H29,-4) -> 40000 | I30: =ROUND(I29,-4) -> 10000 | J30: =ROUND(J29,-4) -> 140000 | K30: =ROUND(K29,-4) -> 0 | ... O30: =ROUND(O29,-4) -> 0
A32: Description | B32: Total | C32: Carry Over | D32: January | E32: February | F32: March | G32: April | H32: May | I32: June | J32: July | K32: Ago | L32: Sep | M32: Oct | N32: Nov | O32: Dec
A33: Fijo - Software de gestión y herramientas digitales | B33: =SUM('2025'!$D33:$O33) -> 777040 | D33: 0 | E33: 0 | F33: 0 | G33: 0 | H33: 0 | I33: 0 | J33: 0 | K33: 0 | L33: =165280 -> 165280 | M33: =120000 -> 120000 | O33: 491760
A34: Fijo - Suscripciones y membresías | B34: =SUM('2025'!$D34:$O34) -> 560276 | D34: 0 | E34: 0 | F34: 0 | G34: 0 | H34: 0 | I34: 0 | J34: 0 | K34: 0 | L34: 0 | M34: =560276 -> 560276
A35: Fijo - Seguros | B35: =SUM('2025'!$D35:$O35) -> 0 | D35: 0 | E35: 0 | F35: 0 | G35: 0 | H35: 0 | I35: 0 | J35: 0 | K35: 0 | L35: 0
A36: Variable - Publicidad y marketing | B36: =SUM('2025'!$D36:$O36) -> 415000 | D36: 0 | E36: 0 | F36: 0 | G36: 0 | H36: 0 | I36: 0 | J36: 0 | K36: 0 | L36: =415000 -> 415000
A37: Variable - Gastos bancarios | B37: =SUM('2025'!$D37:$O37) -> 53633 | D37: 0 | E37: 0 | F37: 0 | G37: 0 | H37: 0 | I37: 0 | J37: 0 | K37: 0 | L37: 0 | M37: 28633 | O37: 25000
A38: Variable - Mantenimiento a equipos | B38: =SUM('2025'!$D38:$O38) -> 0 | D38: 0 | E38: 0 | F38: 0 | G38: 0 | H38: 0 | I38: 0 | J38: 0 | K38: 0 | L38: 0
A39: Variable - Compra de insumos | B39: =SUM('2025'!$D39:$O39) -> 840484 | D39: 0 | E39: 0 | F39: 0 | G39: 0 | H39: 0 | I39: 580000 | J39: 0 | K39: 83985 | L39: =176499 -> 176499
A40: Variable - Compra de insumos a clientes | B40: 0 | D40: 0 | E40: 0 | F40: 0 | G40: 0 | H40: =221925+875468 -> 1097393 | I40: 0 | J40: 0 | K40: 0 | L40: 0 | M40: =560276 -> 560276
A41: Variable - Otros | B41: =SUM('2025'!$D41:$O41) -> 4445611 | D41: 1166810 | E41: 841199 | F41: 25119 | G41: 25005 | H41: 25000 | I41: 25000 | J41: 25026 | K41: 25050 | L41: =25018 -> 25018 | M41: =50000+72000+310500 -> 432500 | N41: =1829884 -> 1829884
A42: Total Monthly Expenses | B42: =SUM(C42:O42) -> 8362953 | D42: =SUM(D33:D41)+D30 -> 1296810 | E42: =SUM(E39:E41) -> 841199 | F42: =SUM(F39:F41) -> 25119 | G42: =SUM(G33:G41) -> 25005 | H42: =SUM(H33:H41) -> 1122393 | I42: =SUM(I33:I41) -> 605000 | J42: =SUM(J33:J41) -> 25026 | K42: =SUM(K33:K41) -> 109035 | L42: =SUM(L33:L41) -> 781797 | M42: =SUM(M33:M41) -> 1701685 | N42: =SUM(N39:N41) -> 1829884 | O42: =SUM(O39:O41) -> 0
A44: Ideal usage | D44: =D25*0.5 -> 740000 | E44: =E25*0.5 -> 615000 | F44: =F25*0.5 -> 0 | G44: =G25*0.5 -> 0 | H44: =H25*0.5 -> 200000 | I44: =I25*0.5 -> 75000 | J44: =J25*0.5 -> 760000 | K44: =K25*0.5 -> 0 | ... O44: =O25*0.5 -> 0
A45: Difference ( - is not good ) | D45: =D44-D42 -> -556810 | E45: =E44-E42 -> -226199 | F45: =F44-F42 -> -25119 | G45: =G44-G42 -> -25005 | H45: =H44-H42 -> -922393 | I45: =I44-I42 -> -530000 | J45: =J44-J42 -> 734974 | K45: =K44-K42 -> -109035 | ... O45: =O44-O42 -> 0
A47: Reinversión en el Negocio: 25%
A48: Description | B48: Total | C48: Carry Over | D48: January | E48: February | F48: March | G48: April | H48: May | I48: June | J48: July | K48: Ago | L48: Sep | M48: Oct | N48: Nov | O48: Dec
...

Sheet 2024
A1: Monthly net income | B1: Total | C1: Carry Over | D1: January | E1: February | F1: March | G1: April | H1: May | I1: June | J1: July | K1: Ago | L1: Sep | M1: Oct | N1: Nov | O1: Dec
A2: Gross revenue | B2: =SUM(C2:O2) -> 23266735 | C2: ='2023'!B2 -> 14963735 | D2: 0 | E2: 0 | F2: 0 | G2: 288000 | H2: 0 | I2: 0 | J2: 2435000 | K2: 2300000 | L2: 1120000 | M2: 1290000 | N2: 360000 | O2: 510000
A3: Monthly Expenses | B3: =SUM(C3:O3) -> 4991983 | C3: =C27 -> 0 | D3: =D27 -> 0 | E3: =E27 -> 214665 | F3: =F27 -> 0 | G3: =G27 -> 137052 | H3: =H27 -> 673680 | I3: =I27 -> 153999 | J3: =J27 -> 220000 | ... L3: =L27 -> 285280 | M3: =285280+1584 -> 286864 | N3: =754419 -> 754419 | O3: =O27 -> 792292
A4: Net Income | B4: =SUM(C4:O4) -> 18274752 | C4: ='2023'!B4 -> 14963735 | D4: =D2-D3 -> 0 | E4: =E2-E3 -> -214665 | F4: =F2-F3 -> 0 | G4: =G2-G3 -> 150948 | H4: =H2-H3 -> -673680 | I4: =I2-I3 -> -153999 | J4: =J2-J3 -> 2215000 | K4: =K2-K3 -> 826268 | ... O4: =O2-O3 -> -282292
A6: Taxes | B6: 0.1 | C6: 0.1 | D6: 0.1 | E6: 0.1 | F6: 0.1 | G6: 0.1 | H6: 0.1 | I6: 0.1 | J6: 0.1 | K6: 0.1 | L6: 0.1 | M6: 0.1 | N6: 0.1 | O6: 0.1
A7: Gross tax | B7: =SUM(C7:O7) -> 2115157.7 | C7: ='2023'!B7 -> 1360339.5 | D7: =D2/11 -> 0 | E7: =E2/11 -> 0 | F7: =F2/11 -> 0 | G7: =G2/11 -> 26181.818 | H7: =H2/11 -> 0 | I7: =I2/11 -> 0 | J7: =J2/11 -> 221363.64 | K7: =K2/11 -> 209090.91 | ... O7: =O2/11 -> 46363.636
A8: Round up tax | B8: =SUM(C8:O8) -> 2240000 | C8: ='2023'!B8 -> 1450000 | D8: =_xlfn.CEILING.MATH(D7, 10000) -> 0 | E8: =_xlfn.CEILING.MATH(E7, 10000) -> 0 | F8: =_xlfn.CEILING.MATH(F7, 10000) -> 0 | G8: =_xlfn.CEILING.MATH(G7, 10000) -> 30000 | H8: =_xlfn.CEILING.MATH(H7, 10000) -> 0 | I8: =_xlfn.CEILING.MATH(I7, 10000) -> 0 | J8: =_xlfn.CEILING.MATH(J7, 10000) -> 230000 | K8: =_xlfn.CEILING.MATH(K7, 10000) -> 210000 | ... O8: =_xlfn.CEILING.MATH(O7, 10000) -> 50000
A10: Gross Owner Access | B10: =SUM(C10:O10) -> 16034752 | C10: ='2023'!B11 -> 13513735 | D10: =D4-D8 -> 0 | E10: =E4-E8 -> -214665 | F10: =F4-F8 -> 0 | G10: =G4-G8 -> 120948 | H10: =H4-H8 -> -673680 | I10: =I4-I8 -> -153999 | J10: =J4-J8 -> 1985000 | K10: =K4-K8 -> 616268 | ... O10: =O4-O8 -> -332292
A12: Monthly Savings | B12: =SUM(C12:O12) -> 7500047.1 | C12: ='2023'!B24 -> 6163908 | D12: =D41 -> 0 | E12: =E41 -> -113772.45 | F12: =F41 -> 0 | G12: =G41 -> 64102.44 | H12: =H41 -> -357050.4 | I12: =I41 -> -81619.47 | J12: =J41 -> 1052050 | K12: =K41 -> 326622.04 | ... O12: =O41 -> -176114.76
A14: Net Owner Access | B14: =SUM(C14:O14) -> 8534704.9 | C14: ='2023'!B28 -> 7349827 | D14: =D10-D12 -> 0 | E14: =E10-E12 -> -100892.55 | F14: =F10-F12 -> 0 | G14: =G10-G12 -> 56845.56 | H14: =H10-H12 -> -316629.6 | I14: =I10-I12 -> -72379.53 | J14: =J10-J12 -> 932950 | K14: =K10-K12 -> 289645.96 | ... O14: =O10-O12 -> -156177.24
A17: Monthly Expenses
A18: New hires | B18: =SUM(C18:O18) -> 0 | D18: 0 | E18: 0 | F18: 0 | G18: 0 | H18: 0 | I18: 0 | J18: 0 | K18: 0 | L18: 0 | M18: 0 | N18: 0 | O18: 0
A19: Equipment purchases | B19: =SUM(C19:O19) -> 789106 | D19: 0 | E19: 0 | F19: 0 | G19: 0 | H19: 0 | I19: 0 | J19: 220000 | K19: 0 | L19: 0 | M19: 0 | N19: 0 | O19: =140000+429106 -> 569106
A20: Product development | B20: =SUM(C20:O20) -> 172920 | D20: 0 | E20: 0 | F20: 0 | G20: 0 | H20: 0 | I20: 0 | J20: 0 | K20: 0 | L20: 0 | M20: 0 | N20: 0 | O20: =157200+15720 -> 172920
A21: Product launches | B21: =SUM(C21:O21) -> 0 | D21: 0 | E21: 0 | F21: 0 | G21: 0 | H21: 0 | I21: 0 | J21: 0 | K21: 0 | L21: 0 | M21: 0 | N21: 0 | O21: 0
A22: Checking account cushion | B22: =SUM(C22:O22) -> 0 | D22: 0 | E22: 0 | F22: 0 | G22: 0 | H22: 0 | I22: 0 | J22: 0 | K22: 0 | L22: 0 | M22: 0 | N22: 0 | O22: 0
A23: Rebrands or website redesigns | B23: =SUM(C23:O23) -> 0 | D23: 0 | E23: 0 | F23: 0 | G23: 0 | H23: 0 | I23: 0 | J23: 0 | K23: 0 | L23: 0 | M23: 0 | N23: 0 | O23: 0
A24: Training programs or certifications | B24: =SUM(C24:O24) -> 0 | D24: 0 | E24: 0 | F24: 0 | G24: 0 | H24: 0 | I24: 0 | J24: 0 | K24: 0 | L24: 0 | M24: 0 | N24: 0 | O24: 0
A25: Emergency funds (which are three to six months of expenses) | B25: =SUM(C25:O25) -> 0 | D25: 0 | E25: 0 | F25: 0 | G25: 0 | H25: 0 | I25: 0 | J25: 0 | K25: 0 | L25: 0 | M25: 0 | N25: 0 | O25: 0
A26: Uncategorised | B26: =SUM(C26:O26) -> 2988674 | D26: 0 | E26: 214665 | F26: 0 | G26: 137052 | H26: 673680 | I26: 153999 | J26: 0 | K26: 1473732 | L26: 285280 | M26: 0 | N26: 0 | O26: =25266+25000 -> 50266
A27: Total Monthly Expenses | B27: =SUM(C27:O27) -> 3950700 | C27: ='2023'!B3 -> 0 | D27: =SUM(D18:D26) -> 0 | E27: =SUM(E18:E26) -> 214665 | F27: =SUM(F18:F26) -> 0 | G27: =SUM(G18:G26) -> 137052 | H27: =SUM(H18:H26) -> 673680 | I27: =SUM(I18:I26) -> 153999 | J27: =SUM(J18:J26) -> 220000 | K27: =SUM(K18:K26) -> 1473732 | ... O27: =SUM(O18:O26) -> 792292
A31: Monthly Savings
A32: New hires | B32: =SUM(C32:O32) -> 25210.17 | D32: =D$10*0.01 -> 0 | E32: =E$10*0.01 -> -2146.65 | F32: =F$10*0.7 -> 0 | G32: =G$10*0.01 -> 1209.48 | H32: =H$10*0.01 -> -6736.8 | I32: =I$10*0.01 -> -1539.99 | J32: =J$10*0.01 -> 19850 | K32: =K$10*0.01 -> 6162.68 | L32: =L$10*0.01 -> 7247.2 | M32: =M$10*0.01 -> 8831.36 | N32: =N$10*0.01 -> -4344.19 | O32: =O$10*0.01 -> -3322.92
A33: Equipment purchases | B33: =SUM(C33:O33) -> 25210.17 | D33: =D$10*0.01 -> 0 | E33: =E$10*0.01 -> -2146.65 | F33: =F$10*0.05 -> 0 | G33: =G$10*0.01 -> 1209.48 | H33: =H$10*0.01 -> -6736.8 | I33: =I$10*0.01 -> -1539.99 | J33: =J$10*0.01 -> 19850 | K33: =K$10*0.01 -> 6162.68 | L33: =L$10*0.01 -> 7247.2 | M33: =M$10*0.01 -> 8831.36 | N33: =N$10*0.01 -> -4344.19 | O33: =O$10*0.01 -> -3322.92
A34: Product development | B34: =SUM(C34:O34) -> 126050.85 | D34: =D$10*0.05 -> 0 | E34: =E$10*0.05 -> -10733.25 | F34: =F$10*0.02 -> 0 | G34: =G$10*0.05 -> 6047.4 | H34: =H$10*0.05 -> -33684 | I34: =I$10*0.05 -> -7699.95 | J34: =J$10*0.05 -> 99250 | K34: =K$10*0.05 -> 30813.4 | L34: =L$10*0.05 -> 36236 | M34: =M$10*0.05 -> 44156.8 | N34: =N$10*0.05 -> -21720.95 | O34: =O$10*0.05 -> -16614.6
A35: Product launches | B35: =SUM(C35:O35) -> 25210.17 | D35: =D$10*0.01 -> 0 | E35: =E$10*0.01 -> -2146.65 | F35: =F$10*0.01 -> 0 | G35: =G$10*0.01 -> 1209.48 | H35: =H$10*0.01 -> -6736.8 | I35: =I$10*0.01 -> -1539.99 | J35: =J$10*0.01 -> 19850 | K35: =K$10*0.01 -> 6162.68 | ... O35: =O$10*0.01 -> -3322.92
A36: Checking account cushion | B36: =SUM(C36:O36) -> 252101.7 | D36: =D$10*0.1 -> 0 | E36: =E$10*0.1 -> -21466.5 | F36: =F$10*0.1 -> 0 | G36: =G$10*0.1 -> 12094.8 | H36: =H$10*0.1 -> -67368 | I36: =I$10*0.1 -> -15399.9 | J36: =J$10*0.1 -> 198500 | K36: =K$10*0.1 -> 61626.8 | ... O36: =O$10*0.1 -> -33229.2
A37: Rebrands or website redesigns | B37: =SUM(C37:O37) -> 126050.85 | D37: =D$10*0.05 -> 0 | E37: =E$10*0.05 -> -10733.25 | F37: =F$10*0.02 -> 0 | G37: =G$10*0.05 -> 6047.4 | H37: =H$10*0.05 -> -33684 | I37: =I$10*0.05 -> -7699.95 | J37: =J$10*0.05 -> 99250 | K37: =K$10*0.05 -> 30813.4 | L37: =L$10*0.05 -> 36236 | M37: =M$10*0.05 -> 44156.8 | N37: =N$10*0.05 -> -21720.95 | O37: =O$10*0.05 -> -16614.6
A38: Training programs or certifications | B38: =SUM(C38:O38) -> 252101.7 | D38: =D$10*0.1 -> 0 | E38: =E$10*0.1 -> -21466.5 | F38: =F$10*0.05 -> 0 | G38: =G$10*0.1 -> 12094.8 | H38: =H$10*0.1 -> -67368 | I38: =I$10*0.1 -> -15399.9 | J38: =J$10*0.1 -> 198500 | K38: =K$10*0.1 -> 61626.8 | L38: =L$10*0.1 -> 72472 | M38: =M$10*0.1 -> 88313.6 | N38: =N$10*0.1 -> -43441.9 | O38: =O$10*0.1 -> -33229.2
A39: Emergency funds (which are three to six months of expenses) | B39: =SUM(C39:O39) -> 252101.7 | D39: =D$10*0.1 -> 0 | E39: =E$10*0.1 -> -21466.5 | F39: =F$10*0.02 -> 0 | G39: =G$10*0.1 -> 12094.8 | H39: =H$10*0.1 -> -67368 | I39: =I$10*0.1 -> -15399.9 | J39: =J$10*0.1 -> 198500 | K39: =K$10*0.1 -> 61626.8 | L39: =L$10*0.1 -> 72472 | M39: =M$10*0.1 -> 88313.6 | N39: =N$10*0.1 -> -43441.9 | O39: =O$10*0.1 -> -33229.2
A40: Uncategorised | B40: =SUM(C40:O40) -> 252101.7 | D40: =D$10*0.1 -> 0 | E40: =E$10*0.1 -> -21466.5 | F40: =F$10*0.02 -> 0 | G40: =G$10*0.1 -> 12094.8 | H40: =H$10*0.1 -> -67368 | I40: =I$10*0.1 -> -15399.9 | J40: =J$10*0.1 -> 198500 | K40: =K$10*0.1 -> 61626.8 | L40: =L$10*0.1 -> 72472 | M40: =M$10*0.1 -> 88313.6 | N40: =N$10*0.1 -> -43441.9 | O40: =O$10*0.1 -> -33229.2
A41: Total Monthly Savings | B41: =SUM(C41:O41) -> 7500047.1 | C41: ='2023'!B24 -> 6163908 | D41: =SUM(D32:D40) -> 0 | E41: =SUM(E32:E40) -> -113772.45 | F41: =SUM(F32:F40) -> 0 | G41: =SUM(G32:G40) -> 64102.44 | H41: =SUM(H32:H40) -> -357050.4 | I41: =SUM(I32:I40) -> -81619.47 | J41: =SUM(J32:J40) -> 1052050 | K41: =SUM(K32:K40) -> 326622.04 | ... O41: =SUM(O32:O40) -> -176114.76

Sheet 2023
A1: Monthly net income | B1: Total | C1: Carry Over | D1: January | E1: February | F1: March | G1: April | H1: May | I1: June | J1: July | K1: Ago | L1: Sep | M1: Oct | N1: Nov | O1: Dec
A2: Gross revenue | B2: =SUM(C2:O2) -> 14963735 | C2: ='2022'!B2 -> 5292735 | D2: 120000 | E2: 1680000 | F2: 915000 | G2: =216000 -> 216000 | H2: 260000 | I2: 360000 | J2: 1190000 | K2: 0 | L2: 480000 | M2: 3550000 | N2: 200000 | O2: 700000
A3: Expenses | B3: =SUM(C3:O3) -> 0 | C3: ='2022'!B3 -> 0 | D3: 0 | E3: 0 | F3: 0 | G3: 0 | H3: 0 | I3: 0 | J3: 0 | K3: 0 | L3: 0 | M3: 0 | N3: 0 | O3: 0
A4: Net Income | B4: =SUM(C4:O4) -> 14963735 | C4: ='2022'!B4 -> 5292735 | D4: =D2-D3 -> 120000 | E4: =E2-E3 -> 1680000 | F4: =F2-F3 -> 915000 | G4: =G2-G3 -> 216000 | H4: =H2-H3 -> 260000 | I4: =I2-I3 -> 360000 | J4: =J2-J3 -> 1190000 | K4: =K2-K3 -> 0 | ... O4: =O2-O3 -> 700000
B5: =SUM(C5:O5) -> 0
A6: Taxes | B6: =SUM(C6:O6) -> 1.2 | C6: ='2022'!B6 | D6: 0.1 | E6: 0.1 | F6: 0.1 | G6: 0.1 | H6: 0.1 | I6: 0.1 | J6: 0.1 | K6: 0.1 | L6: 0.1 | M6: 0.1 | N6: 0.1 | O6: 0.1
A7: Gross tax | B7: =SUM(C7:O7) -> 1360339.5 | C7: ='2022'!B7 -> 481157.73 | D7: =D2/11 -> 10909.091 | E7: =E2/11 -> 152727.27 | F7: =F2/11 -> 83181.818 | G7: =G2/11 -> 19636.364 | H7: =H2/11 -> 23636.364 | I7: =I2/11 -> 32727.273 | J7: =J2/11 -> 108181.82 | K7: =K2/11 -> 0 | ... O7: =O2/11 -> 63636.364
A8: Round up tax | B8: =SUM(C8:O8) -> 1450000 | C8: ='2022'!B8 -> 510000 | D8: =_xlfn.CEILING.MATH(D7, 10000) -> 20000 | E8: =_xlfn.CEILING.MATH(E7, 10000) -> 160000 | F8: =_xlfn.CEILING.MATH(F7, 10000) -> 90000 | G8: =_xlfn.CEILING.MATH(G7, 10000) -> 20000 | H8: =_xlfn.CEILING.MATH(H7, 10000) -> 30000 | I8: =_xlfn.CEILING.MATH(I7, 10000) -> 40000 | J8: =_xlfn.CEILING.MATH(J7, 10000) -> 110000 | K8: =_xlfn.CEILING.MATH(K7, 10000) -> 0 | ... O8: =_xlfn.CEILING.MATH(O7, 10000) -> 70000
A9: Monthly Tax Savings | B9: =SUM(C9:O9) -> 1450000 | C9: ='2022'!B9 -> 510000 | D9: =D8 -> 20000 | E9: =E8 -> 160000 | F9: =F8 -> 90000 | G9: =G8 -> 20000 | H9: =H8 -> 30000 | I9: =I8 -> 40000 | J9: =J8 -> 110000 | K9: =K8 -> 0 | ... O9: =O8 -> 70000
B10: =SUM(C10:O10) -> 0
A11: Gross Owner Access | B11: =SUM(C11:O11) -> 13513735 | C11: ='2022'!B11 -> 4782735 | D11: =D4-D9 -> 100000 | E11: =E4-E9 -> 1520000 | F11: =F4-F9 -> 825000 | G11: =G4-G9 -> 196000 | H11: =H4-H9 -> 230000 | I11: =I4-I9 -> 320000 | J11: =J4-J9 -> 1080000 | K11: =K4-K9 -> 0 | ... O11: =O4-O9 -> 630000
A15: Monthly Savings
A16: New hires | B16: =SUM(C16:O16) -> 704387.35 | C16: ='2022'!B14 -> 47827.35 | D16: =D$11*0.01 -> 1000 | E16: =E$11*0.01 -> 15200 | F16: =F$11*0.7 -> 577500 | G16: =G$11*0.01 -> 1960 | H16: =H$11*0.01 -> 2300 | I16: =I$11*0.01 -> 3200 | J16: =J$11*0.01 -> 10800 | K16: =K$11*0.01 -> 0 | L16: =L$11*0.01 -> 4300 | M16: =M$11*0.01 -> 32200 | N16: =N$11*0.01 -> 1800 | O16: =O$11*0.01 -> 6300
A17: Equipment purchases | B17: =SUM(C17:O17) -> 168137.35 | C17: ='2022'!B15 -> 47827.35 | D17: =D$11*0.01 -> 1000 | E17: =E$11*0.01 -> 15200 | F17: =F$11*0.05 -> 41250 | G17: =G$11*0.01 -> 1960 | H17: =H$11*0.01 -> 2300 | I17: =I$11*0.01 -> 3200 | J17: =J$11*0.01 -> 10800 | K17: =K$11*0.01 -> 0 | L17: =L$11*0.01 -> 4300 | M17: =M$11*0.01 -> 32200 | N17: =N$11*0.01 -> 1800 | O17: =O$11*0.01 -> 6300
A18: Product development | B18: =SUM(C18:O18) -> 650936.75 | C18: ='2022'!B16 -> 239136.75 | D18: =D$11*0.05 -> 5000 | E18: =E$11*0.05 -> 76000 | F18: =F$11*0.02 -> 16500 | G18: =G$11*0.05 -> 9800 | H18: =H$11*0.05 -> 11500 | I18: =I$11*0.05 -> 16000 | J18: =J$11*0.05 -> 54000 | K18: =K$11*0.05 -> 0 | L18: =L$11*0.05 -> 21500 | M18: =M$11*0.05 -> 161000 | N18: =N$11*0.05 -> 9000 | O18: =O$11*0.05 -> 31500
A19: Product launches | B19: =SUM(C19:O19) -> 135137.35 | C19: ='2022'!B17 -> 47827.35 | D19: =D$11*0.01 -> 1000 | E19: =E$11*0.01 -> 15200 | F19: =F$11*0.01 -> 8250 | G19: =G$11*0.01 -> 1960 | H19: =H$11*0.01 -> 2300 | I19: =I$11*0.01 -> 3200 | J19: =J$11*0.01 -> 10800 | K19: =K$11*0.01 -> 0 | ... O19: =O$11*0.01 -> 6300
A20: Checking account cushion | B20: =SUM(C20:O20) -> 1351373.5 | C20: ='2022'!B18 -> 478273.5 | D20: =D$11*0.1 -> 10000 | E20: =E$11*0.1 -> 152000 | F20: =F$11*0.1 -> 82500 | G20: =G$11*0.1 -> 19600 | H20: =H$11*0.1 -> 23000 | I20: =I$11*0.1 -> 32000 | J20: =J$11*0.1 -> 108000 | K20: =K$11*0.1 -> 0 | ... O20: =O$11*0.1 -> 63000
A21: Rebrands or website redesigns | B21: =SUM(C21:O21) -> 650936.75 | C21: ='2022'!B19 -> 239136.75 | D21: =D$11*0.05 -> 5000 | E21: =E$11*0.05 -> 76000 | F21: =F$11*0.02 -> 16500 | G21: =G$11*0.05 -> 9800 | H21: =H$11*0.05 -> 11500 | I21: =I$11*0.05 -> 16000 | J21: =J$11*0.05 -> 54000 | K21: =K$11*0.05 -> 0 | L21: =L$11*0.05 -> 21500 | M21: =M$11*0.05 -> 161000 | N21: =N$11*0.05 -> 9000 | O21: =O$11*0.05 -> 31500
A22: Training programs or certifications | B22: =SUM(C22:O22) -> 1217625.5 | C22: ='2022'!B20 -> 385775.5 | D22: =D$11*0.1 -> 10000 | E22: =E$11*0.1 -> 152000 | F22: =F$11*0.05 -> 41250 | G22: =G$11*0.1 -> 19600 | H22: =H$11*0.1 -> 23000 | I22: =I$11*0.1 -> 32000 | J22: =J$11*0.1 -> 108000 | K22: =K$11*0.1 -> 0 | L22: =L$11*0.1 -> 43000 | M22: =M$11*0.1 -> 322000 | N22: =N$11*0.1 -> 18000 | O22: =O$11*0.1 -> 63000
A23: Emergency funds (which are three to six months of expenses) | B23: =SUM(C23:O23) -> 1285373.5 | C23: ='2022'!B21 -> 478273.5 | D23: =D$11*0.1 -> 10000 | E23: =E$11*0.1 -> 152000 | F23: =F$11*0.02 -> 16500 | G23: =G$11*0.1 -> 19600 | H23: =H$11*0.1 -> 23000 | I23: =I$11*0.1 -> 32000 | J23: =J$11*0.1 -> 108000 | K23: =K$11*0.1 -> 0 | L23: =L$11*0.1 -> 43000 | M23: =M$11*0.1 -> 322000 | N23: =N$11*0.1 -> 18000 | O23: =O$11*0.1 -> 63000
A24: Total Monthly Savings | B24: =SUM(C24:O24) -> 6163908 | C24: ='2022'!B22 -> 1964078.1 | D24: =SUM(D16:D23) -> 43000 | E24: =SUM(E16:E23) -> 653600 | F24: =SUM(F16:F23) -> 800250 | G24: =SUM(G16:G23) -> 84280 | H24: =SUM(H16:H23) -> 98900 | I24: =SUM(I16:I23) -> 137600 | J24: =SUM(J16:J23) -> 464400 | K24: =SUM(K16:K23) -> 0 | ... O24: =SUM(O16:O23) -> 270900
A28: Owner Access | B28: =SUM(C28:O28) -> 7349827 | C28: ='2022'!B24 -> 2818657 | D28: =D11-D24 -> 57000 | E28: =E11-E24 -> 866400 | F28: =F11-F24 -> 24750 | G28: =G11-G24 -> 111720 | H28: =H11-H24 -> 131100 | I28: =I11-I24 -> 182400 | J28: =J11-J24 -> 615600 | K28: =K11-K24 -> 0 | ... O28: =O11-O24 -> 359100

Sheet 2022
A1: Monthly net income | B1: Total | C1: July | D1: August | E1: September | F1: October | G1: November | H1: December
A2: Gross revenue | B2: =SUM(C2:H2) -> 5292735 | C2: 592864 | D2: 575151 | E2: =550000+354720 -> 904720 | F2: 2970000 | G2: 250000
A3: Expenses | B3: =SUM(C3:H3) -> 0 | C3: 0 | D3: 0 | E3: 0 | F3: 0 | G3: 0 | H3: 0
A4: Net Income | B4: =SUM(C4:H4) -> 5292735 | C4: =C2-C3 -> 592864 | D4: =D2-D3 -> 575151 | E4: =E2-E3 -> 904720 | F4: =F2-F3 -> 2970000 | G4: =G2-G3 -> 250000 | H4: =H2-H3 -> 0
A6: Taxes | C6: 0.1 | D6: 0.1 | E6: 0.1 | F6: 0.1 | G6: 0.1 | H6: 0.1
A7: Gross tax | B7: =SUM(C7:H7) -> 481157.73 | C7: =C2/11 -> 53896.727 | D7: =D2/11 -> 52286.455 | E7: =E2/11 -> 82247.273 | F7: =F2/11 -> 270000 | G7: =G2/11 -> 22727.273 | H7: =H2/11 -> 0
A8: Round up tax | B8: =SUM(C8:H8) -> 510000 | C8: =_xlfn.CEILING.MATH(C7, 10000) -> 60000 | D8: =_xlfn.CEILING.MATH(D7, 10000) -> 60000 | E8: =_xlfn.CEILING.MATH(E7, 10000) -> 90000 | F8: =_xlfn.CEILING.MATH(F7, 10000) -> 270000 | G8: =_xlfn.CEILING.MATH(G7, 10000) -> 30000 | H8: =_xlfn.CEILING.MATH(H7, 10) -> 0
A9: Monthly Tax Savings | B9: =SUM(C9:H9) -> 510000 | C9: =C8 -> 60000 | D9: =D8 -> 60000 | E9: =E8 -> 90000 | F9: =F8 -> 270000 | G9: =G8 -> 30000 | H9: =H8 -> 0
A11: Gross Owner Access | B11: =SUM(C11:H11) -> 4782735 | C11: =C4-C9 -> 532864 | D11: =D4-D9 -> 515151 | E11: =E4-E9 -> 814720 | F11: =F4-F9 -> 2700000 | G11: =G4-G9 -> 220000 | H11: =H4-H9 -> 0
A13: Monthly Savings
A14: New hires | B14: =SUM(C14:H14) -> 47827.35 | C14: =$C$11*0.01 -> 5328.64 | D14: =D$11*0.01 -> 5151.51 | E14: =E$11*0.01 -> 8147.2 | F14: =F$11*0.01 -> 27000 | G14: =G$11*0.01 -> 2200 | H14: 0
A15: Equipment purchases | B15: =SUM(C15:H15) -> 47827.35 | C15: =$C$11*0.01 -> 5328.64 | D15: =D$11*0.01 -> 5151.51 | E15: =E$11*0.01 -> 8147.2 | F15: =F$11*0.01 -> 27000 | G15: =G$11*0.01 -> 2200 | H15: 0
A16: Product development | B16: =SUM(C16:H16) -> 239136.75 | C16: =$C$11*0.05 -> 26643.2 | D16: =D$11*0.05 -> 25757.55 | E16: =E$11*0.05 -> 40736 | F16: =F$11*0.05 -> 135000 | G16: =G$11*0.05 -> 11000 | H16: 0
A17: Product launches | B17: =SUM(C17:H17) -> 47827.35 | C17: =$C$11*0.01 -> 5328.64 | D17: =D$11*0.01 -> 5151.51 | E17: =E$11*0.01 -> 8147.2 | F17: =F$11*0.01 -> 27000 | G17: =G$11*0.01 -> 2200 | H17: 0
A18: Checking account cushion | B18: =SUM(C18:H18) -> 478273.5 | C18: =$C$11*0.1 -> 53286.4 | D18: =D$11*0.1 -> 51515.1 | E18: =E$11*0.1 -> 81472 | F18: =F$11*0.1 -> 270000 | G18: =G$11*0.1 -> 22000 | H18: 0
A19: Rebrands or website redesigns | B19: =SUM(C19:H19) -> 239136.75 | C19: =$C$11*0.05 -> 26643.2 | D19: =D$11*0.05 -> 25757.55 | E19: =E$11*0.05 -> 40736 | F19: =F$11*0.05 -> 135000 | G19: =G$11*0.05 -> 11000 | H19: 0
A20: Training programs or certifications | B20: =SUM(C20:H20) -> 385775.5 | C20: =$C$11*0.1 -> 53286.4 | D20: =(D$11*0.1)-92498 -> -40982.9 | E20: =E$11*0.1 -> 81472 | F20: =F$11*0.1 -> 270000 | G20: =G$11*0.1 -> 22000 | H20: 0
A21: Emergency funds (which are three to six months of expenses) | B21: =SUM(C21:H21) -> 478273.5 | C21: =$C$11*0.1 -> 53286.4 | D21: =D$11*0.1 -> 51515.1 | E21: =E$11*0.1 -> 81472 | F21: =F$11*0.1 -> 270000 | G21: =G$11*0.1 -> 22000 | H21: 0
A22: Total Monthly Savings | B22: =SUM(C22:H22) -> 1964078.1 | C22: =SUM(C14:C21) -> 229131.52 | D22: =SUM(D14:D21) -> 129016.93 | E22: =SUM(E14:E21) -> 350329.6 | F22: =SUM(F14:F21) -> 1161000 | G22: =SUM(G14:G21) -> 94600 | H22: =SUM(H14:H21) -> 0
A24: Owner Access | B24: =SUM(C24:H24) -> 2818657 | C24: =C11-C22 -> 303732.48 | D24: =D11-D22 -> 386134.07 | E24: =E11-E22 -> 464390.4 | F24: =F11-F22 -> 1539000 | G24: =G11-G22 -> 125400 | H24: =H11-H22 -> 0
